#VRML_SIM R2025a utf8

EXTERNPROTO "https://raw.githubusercontent.com/cyberbotics/webots/R2023b/projects/objects/backgrounds/protos/TexturedBackground.proto"
EXTERNPROTO "https://raw.githubusercontent.com/cyberbotics/webots/R2023b/projects/objects/backgrounds/protos/TexturedBackgroundLight.proto"
EXTERNPROTO "https://raw.githubusercontent.com/cyberbotics/webots/R2023b/projects/objects/floors/protos/RectangleArena.proto"
EXTERNPROTO "https://raw.githubusercontent.com/cyberbotics/webots/R2023b/projects/objects/factory/containers/protos/WoodenBox.proto"

WorldInfo {
}
Viewpoint {
  orientation -0.00488028551552594 -0.9994531009215026 0.03270599137283224 5.986777647402483
  position -2.331101995677429 0.34903478078145356 1.1551771891180471
  follow "robot"
  followType "Pan and Tilt Shot"
}
TexturedBackground {
}
TexturedBackgroundLight {
}
RectangleArena {
  floorSize 2 2
  floorTileSize 0.25 0.25
  wallHeight 0.05
}
WoodenBox {
  translation -0.365046 0.381129 0.05
  size 0.1 0.1 0.1
}
WoodenBox {
  translation -0.365046 -0.9 0.05
  name "wooden box(2)"
  size 1.1 0.01 0.3
}
WoodenBox {
  translation 0.394954 0.381129 0.05
  name "wooden box(1)"
  size 0.1 0.1 0.1
}
Robot {
  translation 0 0 -0.00361095
  rotation -0.022307661024785968 0.00807064803990979 -0.999718576850415 0
  children [
    Solid {
      translation 0 -0.1 0.15
      children [
        PointLight {
          attenuation 0 0 1
          color 1 0 0
          castShadows TRUE
        }
      ]
      name "LED001_body"
    }
    DistanceSensor {
      translation 0 -0.18 0.17
      rotation 0 0 1 -1.57
      children [
        DEF sensor_eyes Shape {
          appearance PBRAppearance {
            baseColor 0 0 1
            metalness 0
          }
          geometry Box {
            size 0.02 0.05 0.02
          }
        }
      ]
      name "distance_sensor_eyes"
      boundingObject USE sensor_eyes
      physics Physics {
      }
      lookupTable [
        0 0 0
        0.2 2000 0
      ]
    }
    Solid {
      translation 0 -0.155 0.15
      children [
        Shape {
          appearance PBRAppearance {
            baseColor 0.9 0.6 0.5
            roughness 1
            metalness 0
          }
          geometry Box {
            size 0.21 0.05 0.05
          }
        }
      ]
      name "solid(2)"
    }
    BallJoint {
      jointParameters BallJointParameters {
        position -7.153979763308524
        anchor 0 0.14 0.016
      }
      jointParameters2 JointParameters {
        position -0.4171045914282422
      }
      jointParameters3 JointParameters {
        position -15.517346072772774
        axis 0 1 0
      }
      endPoint Solid {
        translation 8.793476023395339e-10 0.13999922255449648 0.01604809087181889
        rotation 0.20786358533237118 -0.8364610431317853 -0.507075589252389 1.379684415526419
        children [
          DEF caster Shape {
            appearance PBRAppearance {
              roughness 1
              metalness 0
            }
            geometry Sphere {
              radius 0.015
            }
          }
        ]
        name "solid(1)"
        boundingObject USE caster
        physics Physics {
        }
      }
    }
    DEF left_hinge HingeJoint {
      jointParameters HingeJointParameters {
        position 50.10771924292946
        anchor -0.119 -0.145 0.0325
      }
      device [
        DEF left_wheel_motor RotationalMotor {
          name "left_wheel_motor"
        }
      ]
      endPoint Solid {
        translation -0.119 -0.145 0.0325
        rotation -0.0786185063366809 0.9938048586483201 -0.07855592522771028 1.576214384273479
        children [
          DEF left_wheel Shape {
            appearance PBRAppearance {
              baseColor 0 0 0
              roughness 1
              metalness 0
            }
            geometry Cylinder {
              height 0.025
              radius 0.0325
            }
          }
        ]
        name "left_hinge_solid"
        boundingObject USE left_wheel
        physics DEF left_wheel_physics Physics {
        }
      }
    }
    DEF robot_main Pose {
      translation 0 0 0.08
      children [
        Shape {
          appearance PBRAppearance {
            baseColor 1 0.7 0.6
            roughness 1
            metalness 0
          }
          geometry Box {
            size 0.21 0.32 0.09
          }
        }
      ]
    }
    DEF right_hinge HingeJoint {
      jointParameters HingeJointParameters {
        position 67.51420800314045
        anchor 0.119 -0.145 0.0325
      }
      device [
        DEF right_wheel_motor RotationalMotor {
          name "right_wheel_motor"
        }
      ]
      endPoint Solid {
        translation 0.1195 -0.145 0.0325
        rotation 0.5833505629465289 -0.5656375047277982 0.5828862101261946 4.171814597202746
        children [
          DEF right_wheel Shape {
            appearance PBRAppearance {
              baseColor 0 0 0
              roughness 1
              metalness 0
            }
            geometry Cylinder {
              height 0.025
              radius 0.0325
            }
          }
        ]
        name "right_hinge_solid"
        boundingObject USE right_wheel
        physics DEF right_wheel_physics Physics {
        }
      }
    }
  ]
  boundingObject USE robot_main
  physics Physics {
  }
  controller "rust_controller"
}
