#VRML_SIM R2023b utf8

EXTERNPROTO "https://raw.githubusercontent.com/cyberbotics/webots/R2023b/projects/objects/backgrounds/protos/TexturedBackground.proto"
EXTERNPROTO "https://raw.githubusercontent.com/cyberbotics/webots/R2023b/projects/objects/backgrounds/protos/TexturedBackgroundLight.proto"
EXTERNPROTO "https://raw.githubusercontent.com/cyberbotics/webots/R2023b/projects/objects/floors/protos/RectangleArena.proto"
EXTERNPROTO "https://raw.githubusercontent.com/cyberbotics/webots/R2023b/projects/objects/factory/containers/protos/WoodenBox.proto"

WorldInfo {
}
Viewpoint {
  orientation -0.2832895402960473 -0.40763245969353423 0.8680914779924138 4.312357858868245
  position 0.18177832033129782 0.3258029132101843 1.2450976526197735
}
TexturedBackground {
}
TexturedBackgroundLight {
}
RectangleArena {
  floorSize 2 2
  floorTileSize 0.25 0.25
  wallHeight 0.05
}
WoodenBox {
  translation -0.365046 0.381129 0.05
  size 0.1 0.1 0.1
}
WoodenBox {
  translation -0.365046 -0.9 0.05
  name "wooden box(2)"
  size 1.1 0.01 0.3
}
WoodenBox {
  translation 0.394954 0.381129 0.05
  name "wooden box(1)"
  size 0.1 0.1 0.1
}
Robot {
  children [
    DistanceSensor {
      translation 0 -0.18 0.17
      rotation 0 0 1 -1.57
      children [
        DEF sensor_eyes Shape {
          appearance PBRAppearance {
            baseColor 0 0 1
            metalness 0
          }
          geometry Box {
            size 0.02 0.05 0.02
          }
        }
      ]
      name "distance_sensor_eyes"
      boundingObject USE sensor_eyes
      physics Physics {
      }
      lookupTable [
        0 0 0
        0.2 2000 0
      ]
    }
    Solid {
      translation 0 -0.155 0.15
      children [
        Shape {
          appearance PBRAppearance {
            baseColor 0.9 0.6 0.5
            roughness 1
            metalness 0
          }
          geometry Box {
            size 0.21 0.05 0.05
          }
        }
      ]
      name "solid(2)"
    }
    BallJoint {
      jointParameters BallJointParameters {
        anchor 0 0.14 0.016
      }
      jointParameters2 JointParameters {
      }
      jointParameters3 JointParameters {
        axis 0 1 0
      }
      endPoint Solid {
        translation 0 0.14 0.016
        children [
          DEF caster Shape {
            appearance PBRAppearance {
              roughness 1
              metalness 0
            }
            geometry Sphere {
              radius 0.015
            }
          }
        ]
        name "solid(1)"
        boundingObject USE caster
        physics Physics {
        }
      }
    }
    DEF left_hinge HingeJoint {
      jointParameters HingeJointParameters {
        anchor -0.119 -0.145 0.0325
      }
      device [
        DEF left_wheel_motor RotationalMotor {
          name "left_wheel_motor"
        }
      ]
      endPoint Solid {
        translation -0.119 -0.145 0.0325
        rotation 0 1 0 1.57
        children [
          DEF left_wheel Shape {
            appearance PBRAppearance {
              baseColor 0 0 0
              roughness 1
              metalness 0
            }
            geometry Cylinder {
              height 0.025
              radius 0.0325
            }
          }
        ]
        name "left_hinge_solid"
        boundingObject USE left_wheel
        physics DEF left_wheel_physics Physics {
        }
      }
    }
    DEF robot_main Pose {
      translation 0 0 0.08
      children [
        Shape {
          appearance PBRAppearance {
            baseColor 1 0.7 0.6
            roughness 1
            metalness 0
          }
          geometry Box {
            size 0.21 0.32 0.09
          }
        }
      ]
    }
    DEF right_hinge HingeJoint {
      jointParameters HingeJointParameters {
        anchor 0.119 -0.145 0.0325
      }
      device [
        DEF right_wheel_motor RotationalMotor {
          name "right_wheel_motor"
        }
      ]
      endPoint Solid {
        translation 0.1195 -0.145 0.0325
        rotation 0 1 0 1.57
        children [
          DEF right_wheel Shape {
            appearance PBRAppearance {
              baseColor 0 0 0
              roughness 1
              metalness 0
            }
            geometry Cylinder {
              height 0.025
              radius 0.0325
            }
          }
        ]
        name "right_hinge_solid"
        boundingObject USE right_wheel
        physics DEF right_wheel_physics Physics {
        }
      }
    }
  ]
  boundingObject USE robot_main
  physics Physics {
  }
  controller "rust_controller"
}
